[2025-05-13T06:10:38.180+0000] {local_task_job_runner.py:123} INFO - ::group::Pre task execution logs
[2025-05-13T06:10:38.217+0000] {taskinstance.py:2613} INFO - Dependencies all met for dep_context=non-requeueable deps ti=<TaskInstance: sec_filing_scheduler.process_alny manual__2025-05-13T06:10:28.574558+00:00 [queued]>
[2025-05-13T06:10:38.243+0000] {taskinstance.py:2613} INFO - Dependencies all met for dep_context=requeueable deps ti=<TaskInstance: sec_filing_scheduler.process_alny manual__2025-05-13T06:10:28.574558+00:00 [queued]>
[2025-05-13T06:10:38.244+0000] {taskinstance.py:2866} INFO - Starting attempt 1 of 1
[2025-05-13T06:10:38.280+0000] {taskinstance.py:2889} INFO - Executing <Task(PythonOperator): process_alny> on 2025-05-13 06:10:28.574558+00:00
[2025-05-13T06:10:38.311+0000] {warnings.py:112} WARNING - /home/***/.local/lib/python3.12/site-packages/***/task/task_runner/standard_task_runner.py:70: DeprecationWarning: This process (pid=1368) is multi-threaded, use of fork() may lead to deadlocks in the child.
  pid = os.fork()

[2025-05-13T06:10:38.324+0000] {standard_task_runner.py:72} INFO - Started process 1377 to run task
[2025-05-13T06:10:38.347+0000] {standard_task_runner.py:104} INFO - Running: ['***', 'tasks', 'run', 'sec_filing_scheduler', 'process_alny', 'manual__2025-05-13T06:10:28.574558+00:00', '--job-id', '29', '--raw', '--subdir', 'DAGS_FOLDER/orchestrate_clinical_pipeline.py', '--cfg-path', '/tmp/tmpfwv5n4wh']
[2025-05-13T06:10:38.353+0000] {standard_task_runner.py:105} INFO - Job 29: Subtask process_alny
[2025-05-13T06:10:38.697+0000] {task_command.py:467} INFO - Running <TaskInstance: sec_filing_scheduler.process_alny manual__2025-05-13T06:10:28.574558+00:00 [running]> on host a05bfec3be05
[2025-05-13T06:10:38.971+0000] {taskinstance.py:3132} INFO - Exporting env vars: AIRFLOW_CTX_DAG_OWNER='***' AIRFLOW_CTX_DAG_ID='sec_filing_scheduler' AIRFLOW_CTX_TASK_ID='process_alny' AIRFLOW_CTX_EXECUTION_DATE='2025-05-13T06:10:28.574558+00:00' AIRFLOW_CTX_TRY_NUMBER='1' AIRFLOW_CTX_DAG_RUN_ID='manual__2025-05-13T06:10:28.574558+00:00'
[2025-05-13T06:10:38.973+0000] {taskinstance.py:731} INFO - ::endgroup::
[2025-05-13T06:10:39.050+0000] {connection.py:277} WARNING - Connection schemes (type: google_cloud_platform) shall not contain '_' according to RFC3986.
[2025-05-13T06:10:39.117+0000] {base.py:84} INFO - Retrieving connection 'google_cloud_default'
[2025-05-13T06:10:40.444+0000] {logging_mixin.py:190} INFO - Found 141 8-K filings
[2025-05-13T06:10:40.445+0000] {logging_mixin.py:190} INFO - Found 13 10-K filings
[2025-05-13T06:10:40.447+0000] {logging_mixin.py:190} INFO - Found 37 10-Q filings
[2025-05-13T06:10:40.449+0000] {logging_mixin.py:190} INFO - Found 191 new filings.
[2025-05-13T06:10:40.450+0000] {logging_mixin.py:190} INFO - Processing 1 filings...
[2025-05-13T06:10:42.263+0000] {connection.py:277} WARNING - Connection schemes (type: google_cloud_platform) shall not contain '_' according to RFC3986.
[2025-05-13T06:10:42.267+0000] {base.py:84} INFO - Retrieving connection 'google_cloud_default'
[2025-05-13T06:10:42.546+0000] {log.py:232} WARNING - [92m06:10:42 - LiteLLM:INFO[0m: utils.py:2870 - 
LiteLLM completion() model= gemini-2.5-pro-preview-05-06; provider = vertex_ai
[2025-05-13T06:10:42.546+0000] {utils.py:2870} INFO - 
LiteLLM completion() model= gemini-2.5-pro-preview-05-06; provider = vertex_ai
[2025-05-13T06:10:42.679+0000] {_metadata.py:142} WARNING - Compute Engine Metadata server unavailable on attempt 1 of 3. Reason: [Errno 111] Connection refused
[2025-05-13T06:10:43.624+0000] {_metadata.py:142} WARNING - Compute Engine Metadata server unavailable on attempt 2 of 3. Reason: [Errno 111] Connection refused
[2025-05-13T06:10:45.532+0000] {_metadata.py:142} WARNING - Compute Engine Metadata server unavailable on attempt 3 of 3. Reason: [Errno 111] Connection refused
[2025-05-13T06:10:45.534+0000] {_default.py:340} WARNING - Authentication failed using Compute Engine authentication due to unavailable metadata server.
[2025-05-13T06:10:45.538+0000] {log.py:232} WARNING - [92m06:10:45 - LiteLLM:ERROR[0m: vertex_llm_base.py:290 - Failed to load vertex credentials. Check to see if credentials containing partial/invalid information.
Traceback (most recent call last):
  File "/home/***/.local/lib/python3.12/site-packages/litellm/llms/vertex_ai/vertex_llm_base.py", line 286, in get_access_token
    _credentials, credential_project_id = self.load_auth(
                                          ^^^^^^^^^^^^^^^
  File "/home/***/.local/lib/python3.12/site-packages/litellm/llms/vertex_ai/vertex_llm_base.py", line 95, in load_auth
    creds, creds_project_id = google_auth.default(
                              ^^^^^^^^^^^^^^^^^^^^
  File "/home/***/.local/lib/python3.12/site-packages/google/auth/_default.py", line 697, in default
    raise exceptions.DefaultCredentialsError(_CLOUD_SDK_MISSING_CREDENTIALS)
google.auth.exceptions.DefaultCredentialsError: Your default credentials were not found. To set up Application Default Credentials, see https://cloud.google.com/docs/authentication/external/set-up-adc for more information.
[2025-05-13T06:10:45.534+0000] {vertex_llm_base.py:290} ERROR - Failed to load vertex credentials. Check to see if credentials containing partial/invalid information.
Traceback (most recent call last):
  File "/home/airflow/.local/lib/python3.12/site-packages/litellm/llms/vertex_ai/vertex_llm_base.py", line 286, in get_access_token
    _credentials, credential_project_id = self.load_auth(
                                          ^^^^^^^^^^^^^^^
  File "/home/airflow/.local/lib/python3.12/site-packages/litellm/llms/vertex_ai/vertex_llm_base.py", line 95, in load_auth
    creds, creds_project_id = google_auth.default(
                              ^^^^^^^^^^^^^^^^^^^^
  File "/home/airflow/.local/lib/python3.12/site-packages/google/auth/_default.py", line 697, in default
    raise exceptions.DefaultCredentialsError(_CLOUD_SDK_MISSING_CREDENTIALS)
google.auth.exceptions.DefaultCredentialsError: Your default credentials were not found. To set up Application Default Credentials, see https://cloud.google.com/docs/authentication/external/set-up-adc for more information.
[2025-05-13T06:10:45.539+0000] {logging_mixin.py:190} INFO - Give Feedback / Get Help: https://github.com/BerriAI/litellm/issues/new
[2025-05-13T06:10:45.540+0000] {logging_mixin.py:190} INFO - LiteLLM.Info: If you need to debug this error, use `litellm._turn_on_debug()'.
[2025-05-13T06:10:45.571+0000] {logging_mixin.py:190} INFO - Finished 1/1: 0001178670-25-000052
[2025-05-13T06:10:45.579+0000] {connection.py:277} WARNING - Connection schemes (type: google_cloud_platform) shall not contain '_' according to RFC3986.
[2025-05-13T06:10:45.580+0000] {base.py:84} INFO - Retrieving connection 'google_cloud_default'
[2025-05-13T06:10:45.617+0000] {log.py:232} WARNING - [92m06:10:45 - LiteLLM:INFO[0m: utils.py:2870 - 
LiteLLM completion() model= gemini-2.5-flash-preview-04-17; provider = vertex_ai
[2025-05-13T06:10:45.617+0000] {utils.py:2870} INFO - 
LiteLLM completion() model= gemini-2.5-flash-preview-04-17; provider = vertex_ai
[2025-05-13T06:10:45.655+0000] {_metadata.py:142} WARNING - Compute Engine Metadata server unavailable on attempt 1 of 3. Reason: [Errno 111] Connection refused
[2025-05-13T06:10:46.701+0000] {_metadata.py:142} WARNING - Compute Engine Metadata server unavailable on attempt 2 of 3. Reason: [Errno 111] Connection refused
[2025-05-13T06:10:48.862+0000] {_metadata.py:142} WARNING - Compute Engine Metadata server unavailable on attempt 3 of 3. Reason: [Errno 111] Connection refused
[2025-05-13T06:10:48.863+0000] {_default.py:340} WARNING - Authentication failed using Compute Engine authentication due to unavailable metadata server.
[2025-05-13T06:10:48.864+0000] {log.py:232} WARNING - [92m06:10:48 - LiteLLM:ERROR[0m: vertex_llm_base.py:290 - Failed to load vertex credentials. Check to see if credentials containing partial/invalid information.
Traceback (most recent call last):
  File "/home/***/.local/lib/python3.12/site-packages/litellm/llms/vertex_ai/vertex_llm_base.py", line 286, in get_access_token
    _credentials, credential_project_id = self.load_auth(
                                          ^^^^^^^^^^^^^^^
  File "/home/***/.local/lib/python3.12/site-packages/litellm/llms/vertex_ai/vertex_llm_base.py", line 95, in load_auth
    creds, creds_project_id = google_auth.default(
                              ^^^^^^^^^^^^^^^^^^^^
  File "/home/***/.local/lib/python3.12/site-packages/google/auth/_default.py", line 697, in default
    raise exceptions.DefaultCredentialsError(_CLOUD_SDK_MISSING_CREDENTIALS)
google.auth.exceptions.DefaultCredentialsError: Your default credentials were not found. To set up Application Default Credentials, see https://cloud.google.com/docs/authentication/external/set-up-adc for more information.
[2025-05-13T06:10:48.864+0000] {vertex_llm_base.py:290} ERROR - Failed to load vertex credentials. Check to see if credentials containing partial/invalid information.
Traceback (most recent call last):
  File "/home/airflow/.local/lib/python3.12/site-packages/litellm/llms/vertex_ai/vertex_llm_base.py", line 286, in get_access_token
    _credentials, credential_project_id = self.load_auth(
                                          ^^^^^^^^^^^^^^^
  File "/home/airflow/.local/lib/python3.12/site-packages/litellm/llms/vertex_ai/vertex_llm_base.py", line 95, in load_auth
    creds, creds_project_id = google_auth.default(
                              ^^^^^^^^^^^^^^^^^^^^
  File "/home/airflow/.local/lib/python3.12/site-packages/google/auth/_default.py", line 697, in default
    raise exceptions.DefaultCredentialsError(_CLOUD_SDK_MISSING_CREDENTIALS)
google.auth.exceptions.DefaultCredentialsError: Your default credentials were not found. To set up Application Default Credentials, see https://cloud.google.com/docs/authentication/external/set-up-adc for more information.
[2025-05-13T06:10:48.865+0000] {logging_mixin.py:190} INFO - Give Feedback / Get Help: https://github.com/BerriAI/litellm/issues/new
[2025-05-13T06:10:48.866+0000] {logging_mixin.py:190} INFO - LiteLLM.Info: If you need to debug this error, use `litellm._turn_on_debug()'.
[2025-05-13T06:10:48.878+0000] {logging_mixin.py:190} INFO - Error processing filings: litellm.APIConnectionError: Your default credentials were not found. To set up Application Default Credentials, see https://cloud.google.com/docs/authentication/external/set-up-adc for more information.
Traceback (most recent call last):
  File "/home/***/.local/lib/python3.12/site-packages/litellm/main.py", line 2500, in completion
    model_response = vertex_chat_completion.completion(  # type: ignore
                     ^^^^^^^^^^^^^^^^^^^^^^^^^^^^^^^^^^^^^^^^^^^^^^^^^^
  File "/home/***/.local/lib/python3.12/site-packages/litellm/llms/vertex_ai/gemini/vertex_and_google_ai_studio_gemini.py", line 1436, in completion
    _auth_header, vertex_project = self._ensure_access_token(
                                   ^^^^^^^^^^^^^^^^^^^^^^^^^^
  File "/home/***/.local/lib/python3.12/site-packages/litellm/llms/vertex_ai/vertex_llm_base.py", line 135, in _ensure_access_token
    return self.get_access_token(
           ^^^^^^^^^^^^^^^^^^^^^^
  File "/home/***/.local/lib/python3.12/site-packages/litellm/llms/vertex_ai/vertex_llm_base.py", line 293, in get_access_token
    raise e
  File "/home/***/.local/lib/python3.12/site-packages/litellm/llms/vertex_ai/vertex_llm_base.py", line 286, in get_access_token
    _credentials, credential_project_id = self.load_auth(
                                          ^^^^^^^^^^^^^^^
  File "/home/***/.local/lib/python3.12/site-packages/litellm/llms/vertex_ai/vertex_llm_base.py", line 95, in load_auth
    creds, creds_project_id = google_auth.default(
                              ^^^^^^^^^^^^^^^^^^^^
  File "/home/***/.local/lib/python3.12/site-packages/google/auth/_default.py", line 697, in default
    raise exceptions.DefaultCredentialsError(_CLOUD_SDK_MISSING_CREDENTIALS)
google.auth.exceptions.DefaultCredentialsError: Your default credentials were not found. To set up Application Default Credentials, see https://cloud.google.com/docs/authentication/external/set-up-adc for more information.
[2025-05-13T06:10:49.258+0000] {logging_mixin.py:190} INFO - Updated processed accessions in GCS.
[2025-05-13T06:10:49.262+0000] {logging_mixin.py:190} INFO - Deleted output_dir: sec_data/ALNY
[2025-05-13T06:10:49.263+0000] {python.py:240} INFO - Done. Returned value was: None
[2025-05-13T06:10:49.272+0000] {taskinstance.py:340} INFO - ::group::Post task execution logs
[2025-05-13T06:10:49.273+0000] {taskinstance.py:352} INFO - Marking task as SUCCESS. dag_id=sec_filing_scheduler, task_id=process_alny, run_id=manual__2025-05-13T06:10:28.574558+00:00, execution_date=20250513T061028, start_date=20250513T061038, end_date=20250513T061049
[2025-05-13T06:10:49.338+0000] {local_task_job_runner.py:266} INFO - Task exited with return code 0
[2025-05-13T06:10:49.349+0000] {taskinstance.py:3895} INFO - 0 downstream tasks scheduled from follow-on schedule check
[2025-05-13T06:10:49.354+0000] {local_task_job_runner.py:245} INFO - ::endgroup::
