[2025-05-13T05:24:25.279+0000] {local_task_job_runner.py:123} INFO - ::group::Pre task execution logs
[2025-05-13T05:24:25.302+0000] {taskinstance.py:2613} INFO - Dependencies all met for dep_context=non-requeueable deps ti=<TaskInstance: sec_filing_scheduler.process_wve manual__2025-05-13T05:24:05.919913+00:00 [queued]>
[2025-05-13T05:24:25.324+0000] {taskinstance.py:2613} INFO - Dependencies all met for dep_context=requeueable deps ti=<TaskInstance: sec_filing_scheduler.process_wve manual__2025-05-13T05:24:05.919913+00:00 [queued]>
[2025-05-13T05:24:25.343+0000] {taskinstance.py:2866} INFO - Starting attempt 1 of 1
[2025-05-13T05:24:25.434+0000] {taskinstance.py:2889} INFO - Executing <Task(PythonOperator): process_wve> on 2025-05-13 05:24:05.919913+00:00
[2025-05-13T05:24:25.637+0000] {warnings.py:112} WARNING - /home/***/.local/lib/python3.12/site-packages/***/task/task_runner/standard_task_runner.py:70: DeprecationWarning: This process (pid=735) is multi-threaded, use of fork() may lead to deadlocks in the child.
  pid = os.fork()

[2025-05-13T05:24:25.687+0000] {standard_task_runner.py:72} INFO - Started process 744 to run task
[2025-05-13T05:24:25.710+0000] {standard_task_runner.py:104} INFO - Running: ['***', 'tasks', 'run', 'sec_filing_scheduler', 'process_wve', 'manual__2025-05-13T05:24:05.919913+00:00', '--job-id', '11', '--raw', '--subdir', 'DAGS_FOLDER/orchestrate_clinical_pipeline.py', '--cfg-path', '/tmp/tmp2d8sjy34']
[2025-05-13T05:24:25.731+0000] {standard_task_runner.py:105} INFO - Job 11: Subtask process_wve
[2025-05-13T05:24:26.183+0000] {task_command.py:467} INFO - Running <TaskInstance: sec_filing_scheduler.process_wve manual__2025-05-13T05:24:05.919913+00:00 [running]> on host a05bfec3be05
[2025-05-13T05:24:26.650+0000] {taskinstance.py:3132} INFO - Exporting env vars: AIRFLOW_CTX_DAG_OWNER='***' AIRFLOW_CTX_DAG_ID='sec_filing_scheduler' AIRFLOW_CTX_TASK_ID='process_wve' AIRFLOW_CTX_EXECUTION_DATE='2025-05-13T05:24:05.919913+00:00' AIRFLOW_CTX_TRY_NUMBER='1' AIRFLOW_CTX_DAG_RUN_ID='manual__2025-05-13T05:24:05.919913+00:00'
[2025-05-13T05:24:26.652+0000] {taskinstance.py:731} INFO - ::endgroup::
[2025-05-13T05:24:26.660+0000] {taskinstance.py:3311} ERROR - Task failed with exception
Traceback (most recent call last):
  File "/home/airflow/.local/lib/python3.12/site-packages/airflow/models/taskinstance.py", line 767, in _execute_task
    result = _execute_callable(context=context, **execute_callable_kwargs)
             ^^^^^^^^^^^^^^^^^^^^^^^^^^^^^^^^^^^^^^^^^^^^^^^^^^^^^^^^^^^^^
  File "/home/airflow/.local/lib/python3.12/site-packages/airflow/models/taskinstance.py", line 733, in _execute_callable
    return ExecutionCallableRunner(
           ^^^^^^^^^^^^^^^^^^^^^^^^
  File "/home/airflow/.local/lib/python3.12/site-packages/airflow/utils/operator_helpers.py", line 252, in run
    return self.func(*args, **kwargs)
           ^^^^^^^^^^^^^^^^^^^^^^^^^^
  File "/home/airflow/.local/lib/python3.12/site-packages/airflow/models/baseoperator.py", line 422, in wrapper
    return func(self, *args, **kwargs)
           ^^^^^^^^^^^^^^^^^^^^^^^^^^^
  File "/home/airflow/.local/lib/python3.12/site-packages/airflow/operators/python.py", line 238, in execute
    return_value = self.execute_callable()
                   ^^^^^^^^^^^^^^^^^^^^^^^
  File "/home/airflow/.local/lib/python3.12/site-packages/airflow/operators/python.py", line 256, in execute_callable
    return runner.run(*self.op_args, **self.op_kwargs)
           ^^^^^^^^^^^^^^^^^^^^^^^^^^^^^^^^^^^^^^^^^^^
  File "/home/airflow/.local/lib/python3.12/site-packages/airflow/utils/operator_helpers.py", line 252, in run
    return self.func(*args, **kwargs)
           ^^^^^^^^^^^^^^^^^^^^^^^^^^
  File "/opt/airflow/dags/orchestrate_clinical_pipeline.py", line 21, in process_ticker_func
    extractor = SECFilingExtractor(ticker=ticker, email="tanmayp@gmail.com", output_dir=f"sec_data/{ticker}")
                ^^^^^^^^^^^^^^^^^^^^^^^^^^^^^^^^^^^^^^^^^^^^^^^^^^^^^^^^^^^^^^^^^^^^^^^^^^^^^^^^^^^^^^^^^^^^^
  File "/opt/airflow/dags/utils/test.py", line 42, in __init__
    self.credentials = service_account.Credentials.from_service_account_file(self.cred_path)
                       ^^^^^^^^^^^^^^^^^^^^^^^^^^^^^^^^^^^^^^^^^^^^^^^^^^^^^^^^^^^^^^^^^^^^^
  File "/home/airflow/.local/lib/python3.12/site-packages/google/oauth2/service_account.py", line 260, in from_service_account_file
    info, signer = _service_account_info.from_filename(
                   ^^^^^^^^^^^^^^^^^^^^^^^^^^^^^^^^^^^^
  File "/home/airflow/.local/lib/python3.12/site-packages/google/auth/_service_account_info.py", line 78, in from_filename
    with io.open(filename, "r", encoding="utf-8") as json_file:
         ^^^^^^^^^^^^^^^^^^^^^^^^^^^^^^^^^^^^^^^^
FileNotFoundError: [Errno 2] No such file or directory: 'D:\\Kcap\\backend\\gcp\\clinical-data-keys.json'
[2025-05-13T05:24:26.712+0000] {taskinstance.py:1225} INFO - Marking task as FAILED. dag_id=sec_filing_scheduler, task_id=process_wve, run_id=manual__2025-05-13T05:24:05.919913+00:00, execution_date=20250513T052405, start_date=20250513T052425, end_date=20250513T052426
[2025-05-13T05:24:26.744+0000] {taskinstance.py:340} INFO - ::group::Post task execution logs
[2025-05-13T05:24:26.745+0000] {standard_task_runner.py:124} ERROR - Failed to execute job 11 for task process_wve ([Errno 2] No such file or directory: 'D:\\Kcap\\backend\\gcp\\clinical-data-keys.json'; 744)
Traceback (most recent call last):
  File "/home/airflow/.local/lib/python3.12/site-packages/airflow/task/task_runner/standard_task_runner.py", line 117, in _start_by_fork
    ret = args.func(args, dag=self.dag)
          ^^^^^^^^^^^^^^^^^^^^^^^^^^^^^
  File "/home/airflow/.local/lib/python3.12/site-packages/airflow/cli/cli_config.py", line 49, in command
    return func(*args, **kwargs)
           ^^^^^^^^^^^^^^^^^^^^^
  File "/home/airflow/.local/lib/python3.12/site-packages/airflow/utils/cli.py", line 116, in wrapper
    return f(*args, **kwargs)
           ^^^^^^^^^^^^^^^^^^
  File "/home/airflow/.local/lib/python3.12/site-packages/airflow/cli/commands/task_command.py", line 483, in task_run
    task_return_code = _run_task_by_selected_method(args, _dag, ti)
                       ^^^^^^^^^^^^^^^^^^^^^^^^^^^^^^^^^^^^^^^^^^^^
  File "/home/airflow/.local/lib/python3.12/site-packages/airflow/cli/commands/task_command.py", line 256, in _run_task_by_selected_method
    return _run_raw_task(args, ti)
           ^^^^^^^^^^^^^^^^^^^^^^^
  File "/home/airflow/.local/lib/python3.12/site-packages/airflow/cli/commands/task_command.py", line 341, in _run_raw_task
    return ti._run_raw_task(
           ^^^^^^^^^^^^^^^^^
  File "/home/airflow/.local/lib/python3.12/site-packages/airflow/utils/session.py", line 97, in wrapper
    return func(*args, session=session, **kwargs)
           ^^^^^^^^^^^^^^^^^^^^^^^^^^^^^^^^^^^^^^
  File "/home/airflow/.local/lib/python3.12/site-packages/airflow/models/taskinstance.py", line 3005, in _run_raw_task
    return _run_raw_task(
           ^^^^^^^^^^^^^^
  File "/home/airflow/.local/lib/python3.12/site-packages/airflow/models/taskinstance.py", line 273, in _run_raw_task
    TaskInstance._execute_task_with_callbacks(
  File "/home/airflow/.local/lib/python3.12/site-packages/airflow/models/taskinstance.py", line 3159, in _execute_task_with_callbacks
    result = self._execute_task(context, task_orig)
             ^^^^^^^^^^^^^^^^^^^^^^^^^^^^^^^^^^^^^^
  File "/home/airflow/.local/lib/python3.12/site-packages/airflow/models/taskinstance.py", line 3183, in _execute_task
    return _execute_task(self, context, task_orig)
           ^^^^^^^^^^^^^^^^^^^^^^^^^^^^^^^^^^^^^^^
  File "/home/airflow/.local/lib/python3.12/site-packages/airflow/models/taskinstance.py", line 767, in _execute_task
    result = _execute_callable(context=context, **execute_callable_kwargs)
             ^^^^^^^^^^^^^^^^^^^^^^^^^^^^^^^^^^^^^^^^^^^^^^^^^^^^^^^^^^^^^
  File "/home/airflow/.local/lib/python3.12/site-packages/airflow/models/taskinstance.py", line 733, in _execute_callable
    return ExecutionCallableRunner(
           ^^^^^^^^^^^^^^^^^^^^^^^^
  File "/home/airflow/.local/lib/python3.12/site-packages/airflow/utils/operator_helpers.py", line 252, in run
    return self.func(*args, **kwargs)
           ^^^^^^^^^^^^^^^^^^^^^^^^^^
  File "/home/airflow/.local/lib/python3.12/site-packages/airflow/models/baseoperator.py", line 422, in wrapper
    return func(self, *args, **kwargs)
           ^^^^^^^^^^^^^^^^^^^^^^^^^^^
  File "/home/airflow/.local/lib/python3.12/site-packages/airflow/operators/python.py", line 238, in execute
    return_value = self.execute_callable()
                   ^^^^^^^^^^^^^^^^^^^^^^^
  File "/home/airflow/.local/lib/python3.12/site-packages/airflow/operators/python.py", line 256, in execute_callable
    return runner.run(*self.op_args, **self.op_kwargs)
           ^^^^^^^^^^^^^^^^^^^^^^^^^^^^^^^^^^^^^^^^^^^
  File "/home/airflow/.local/lib/python3.12/site-packages/airflow/utils/operator_helpers.py", line 252, in run
    return self.func(*args, **kwargs)
           ^^^^^^^^^^^^^^^^^^^^^^^^^^
  File "/opt/airflow/dags/orchestrate_clinical_pipeline.py", line 21, in process_ticker_func
    extractor = SECFilingExtractor(ticker=ticker, email="tanmayp@gmail.com", output_dir=f"sec_data/{ticker}")
                ^^^^^^^^^^^^^^^^^^^^^^^^^^^^^^^^^^^^^^^^^^^^^^^^^^^^^^^^^^^^^^^^^^^^^^^^^^^^^^^^^^^^^^^^^^^^^
  File "/opt/airflow/dags/utils/test.py", line 42, in __init__
    self.credentials = service_account.Credentials.from_service_account_file(self.cred_path)
                       ^^^^^^^^^^^^^^^^^^^^^^^^^^^^^^^^^^^^^^^^^^^^^^^^^^^^^^^^^^^^^^^^^^^^^
  File "/home/airflow/.local/lib/python3.12/site-packages/google/oauth2/service_account.py", line 260, in from_service_account_file
    info, signer = _service_account_info.from_filename(
                   ^^^^^^^^^^^^^^^^^^^^^^^^^^^^^^^^^^^^
  File "/home/airflow/.local/lib/python3.12/site-packages/google/auth/_service_account_info.py", line 78, in from_filename
    with io.open(filename, "r", encoding="utf-8") as json_file:
         ^^^^^^^^^^^^^^^^^^^^^^^^^^^^^^^^^^^^^^^^
FileNotFoundError: [Errno 2] No such file or directory: 'D:\\Kcap\\backend\\gcp\\clinical-data-keys.json'
[2025-05-13T05:24:26.784+0000] {local_task_job_runner.py:266} INFO - Task exited with return code 1
[2025-05-13T05:24:26.828+0000] {taskinstance.py:3895} INFO - 0 downstream tasks scheduled from follow-on schedule check
[2025-05-13T05:24:26.832+0000] {local_task_job_runner.py:245} INFO - ::endgroup::
